#VRML_SIM R2023b utf8

EXTERNPROTO "https://raw.githubusercontent.com/cyberbotics/webots/R2023b/projects/appearances/protos/BrushedSteel.proto"
EXTERNPROTO "https://raw.githubusercontent.com/cyberbotics/webots/R2023b/projects/appearances/protos/DamascusSteel.proto"
EXTERNPROTO "https://raw.githubusercontent.com/cyberbotics/webots/R2023b/projects/appearances/protos/HammeredCopper.proto"
EXTERNPROTO "https://raw.githubusercontent.com/cyberbotics/webots/R2023b/projects/objects/backgrounds/protos/TexturedBackground.proto"
EXTERNPROTO "https://raw.githubusercontent.com/cyberbotics/webots/R2023b/projects/objects/backgrounds/protos/TexturedBackgroundLight.proto"
EXTERNPROTO "https://raw.githubusercontent.com/cyberbotics/webots/R2023b/projects/objects/floors/protos/UnevenTerrain.proto"
EXTERNPROTO "https://raw.githubusercontent.com/cyberbotics/webots/R2023b/projects/appearances/protos/RoughConcrete.proto"
EXTERNPROTO "https://raw.githubusercontent.com/cyberbotics/webots/R2023b/projects/appearances/protos/ElectricConduit.proto"
EXTERNPROTO "https://raw.githubusercontent.com/cyberbotics/webots/R2023b/projects/appearances/protos/GalvanizedMetal.proto"
EXTERNPROTO "https://raw.githubusercontent.com/cyberbotics/webots/R2023b/projects/appearances/protos/GlossyPaint.proto"
EXTERNPROTO "https://raw.githubusercontent.com/cyberbotics/webots/R2023b/projects/appearances/protos/CorrugatedPvc.proto"

WorldInfo {
}
Viewpoint {
  orientation -0.24430715586446444 0.49940530405234224 0.831208972447846 0.9329040529071612
  position -50.67099659339835 -40.18939890610947 28.044072116930863
}
TexturedBackground {
  texture "dawn_cloudy_empty"
}
TexturedBackgroundLight {
  luminosity 2
}
UnevenTerrain {
  translation 0 0 -4.44
  appearance RoughConcrete {
  }
}
Robot {
  translation 6.292444591989498 -2.5290349754316765 -0.845725809611504
  rotation -0.01658649488070897 -0.05603504441077567 0.9982910206875821 2.863660858750936
  children [
    Transform {
      translation 1.01962e-07 0 0.1
      rotation 0 1 0 -1.5707953071795862
      scale 1.7 1.7 1
      children [
        DEF body Shape {
          appearance GalvanizedMetal {
            colorOverride 0 0.666667 1
          }
          geometry Cylinder {
            height 0.7
            radius 0.2
          }
        }
      ]
    }
    DistanceSensor {
      translation -0.35 -0.14 0.22
      rotation 0 0 1 -2.5
      children [
        DEF ds Shape {
          appearance GlossyPaint {
            baseColor 1 0 0
          }
          geometry Sphere {
            radius 0.05
          }
        }
      ]
      name "ds1"
      boundingObject USE ds
      physics Physics {
        mass 1
      }
      translationStep 0.11
      lookupTable [
        0 0 0
        0.5 1000 0
      ]
      aperture 1.5715
    }
    DistanceSensor {
      translation -0.35 0.15 0.22
      rotation 0 0 1 2.6763956132800115
      children [
        DEF ds2 Shape {
          appearance GlossyPaint {
            baseColor 1 0 0
          }
          geometry Sphere {
            radius 0.05
          }
        }
      ]
      name "ds2"
      boundingObject USE ds2
      physics Physics {
        mass 1
      }
      lookupTable [
        0 0 0
        0.5 1000 0
      ]
    }
    Solid {
      translation -0.18 -0.24 0
      children [
        Solid {
          translation -0.00017766252744422228 -0.017340268664742475 0.05993637531167906
          rotation -0.9999999929357695 8.124469320562993e-05 -8.676267159571073e-05 1.5708626067521982
          children [
            DEF cylinder1 Shape {
              appearance DamascusSteel {
              }
              geometry Cylinder {
                height 0.09
                radius 0.02
              }
            }
            Solid {
              translation 0 0 -0.05
              children [
                DEF sphere1 Shape {
                  appearance BrushedSteel {
                  }
                  geometry Sphere {
                    radius 0.02
                  }
                }
                Solid {
                  translation 0 0.1 1.79608e-07
                  rotation -1 0 0 -1.5707953071795862
                  children [
                    DEF cylinder2 Shape {
                      appearance BrushedSteel {
                      }
                      geometry Cylinder {
                        height 0.2
                        radius 0.02
                      }
                    }
                    Solid {
                      translation 0 0 -0.11
                      children [
                        DEF sphere1 Shape {
                          appearance BrushedSteel {
                          }
                          geometry Sphere {
                            radius 0.02
                          }
                        }
                        Solid {
                          translation 0 -0.03 -9.99999e-08
                          rotation 1 0 0 1.5708
                          children [
                            DEF cylinder3 Shape {
                              appearance BrushedSteel {
                              }
                              geometry Cylinder {
                                height 0.06
                                radius 0.02
                              }
                            }
                            HingeJoint {
                              jointParameters HingeJointParameters {
                                position 431.27543311299917
                                axis 0 0 1
                                anchor -9.51224e-05 0.00113507 0.0800056
                              }
                              device [
                                RotationalMotor {
                                  name "wheel1_left"
                                }
                              ]
                              endPoint Solid {
                                translation -0.0019924602241111304 -0.00016145407771036603 0.07996235016853431
                                rotation -3.439470055311559e-06 -4.6353230388819775e-06 -0.9999999999833419 2.252473758471568
                                children [
                                  DEF wheel Shape {
                                    appearance ElectricConduit {
                                    }
                                    geometry Cylinder {
                                      height 0.09
                                      radius 0.15
                                    }
                                  }
                                ]
                                boundingObject USE wheel
                                physics Physics {
                                  mass 1
                                }
                                linearVelocity -0.004028455061305113 0.0020826418499131343 -0.008378806542638274
                                angularVelocity 1.0889868811307954 3.8221324602595366 0.45740172455538985
                              }
                            }
                          ]
                          boundingObject USE cylinder3
                          physics DEF phy1 Physics {
                            mass 1
                          }
                        }
                      ]
                      name "solid(1)"
                      boundingObject USE sphere1
                      physics USE phy1
                    }
                  ]
                  boundingObject USE cylinder2
                  physics USE phy1
                }
              ]
              boundingObject USE sphere1
              physics USE phy1
            }
          ]
          boundingObject USE cylinder1
          physics USE phy1
        }
      ]
      name "wheel1_left_system"
      physics DEF phy1 Physics {
        mass 1
      }
    }
    Solid {
      translation 0.18 -0.24 0
      children [
        Solid {
          translation -0.0001757815149209252 -0.017333744024692788 0.0600545153188472
          rotation -0.9999999930027248 7.374603208071159e-05 -9.249904417794078e-05 1.5708786387286822
          children [
            DEF cylinder1 Shape {
              appearance DamascusSteel {
              }
              geometry Cylinder {
                height 0.09
                radius 0.02
              }
            }
            Solid {
              translation 0 0 -0.05
              children [
                DEF sphere1 Shape {
                  appearance BrushedSteel {
                  }
                  geometry Sphere {
                    radius 0.02
                  }
                }
                Solid {
                  translation 0 0.1 1.79608e-07
                  rotation -1 0 0 -1.5707953071795862
                  children [
                    DEF cylinder2 Shape {
                      appearance BrushedSteel {
                      }
                      geometry Cylinder {
                        height 0.2
                        radius 0.02
                      }
                    }
                    Solid {
                      translation 0 0 -0.11
                      children [
                        DEF sphere1 Shape {
                          appearance BrushedSteel {
                          }
                          geometry Sphere {
                            radius 0.02
                          }
                        }
                        Solid {
                          translation 0 -0.03 -9.99999e-08
                          rotation 1 0 0 1.5708
                          children [
                            DEF cylinder3 Shape {
                              appearance BrushedSteel {
                              }
                              geometry Cylinder {
                                height 0.06
                                radius 0.02
                              }
                            }
                            HingeJoint {
                              jointParameters HingeJointParameters {
                                position 125.05601459759
                                axis 0 0 1
                                anchor 0.000341778 0.000558794 0.0800055
                              }
                              device [
                                RotationalMotor {
                                  name "wheel2_left"
                                }
                              ]
                              endPoint Solid {
                                translation -0.00029348442071023623 -0.00037723336607528807 0.07993854881136875
                                rotation -5.304246750399013e-06 -1.0784147540084637e-05 -0.9999999999277835 0.5969376740287099
                                children [
                                  DEF wheel Shape {
                                    appearance ElectricConduit {
                                    }
                                    geometry Cylinder {
                                      height 0.09
                                      radius 0.15
                                    }
                                  }
                                ]
                                boundingObject USE wheel
                                physics Physics {
                                  mass 1
                                }
                                linearVelocity -0.0032688238815495162 0.0012325690144558818 -0.002926295183870369
                                angularVelocity 1.0889770094617413 3.822127532627014 0.45746528403337416
                              }
                            }
                          ]
                          boundingObject USE cylinder3
                          physics DEF phy1 Physics {
                            mass 1
                          }
                        }
                      ]
                      name "solid(1)"
                      boundingObject USE sphere1
                      physics USE phy1
                    }
                  ]
                  boundingObject USE cylinder2
                  physics USE phy1
                }
              ]
              boundingObject USE sphere1
              physics USE phy1
            }
          ]
          boundingObject USE cylinder1
          physics USE phy1
        }
      ]
      name "wheel2_left_system"
      physics USE phy1
    }
    Solid {
      translation -0.18 0.24 0
      children [
        Solid {
          translation -0.000177663 0.0173403 0.0599364
          rotation -0.9999999929357695 8.124469320562993e-05 -8.676267159571073e-05 1.5708626067521982
          children [
            DEF cylinder1 Shape {
              appearance DamascusSteel {
              }
              geometry Cylinder {
                height 0.09
                radius 0.02
              }
            }
            Solid {
              translation 0 0 0.05
              children [
                DEF sphere1 Shape {
                  appearance BrushedSteel {
                  }
                  geometry Sphere {
                    radius 0.02
                  }
                }
                Solid {
                  translation 0 0.1 1.79608e-07
                  rotation -1 0 0 -1.5707953071795862
                  children [
                    DEF cylinder2 Shape {
                      appearance BrushedSteel {
                      }
                      geometry Cylinder {
                        height 0.2
                        radius 0.02
                      }
                    }
                    Solid {
                      translation 0 0 -0.11
                      children [
                        DEF sphere1 Shape {
                          appearance BrushedSteel {
                          }
                          geometry Sphere {
                            radius 0.02
                          }
                        }
                        Solid {
                          translation 0 0.03 -9.99999e-08
                          rotation 1 0 0 1.5708
                          children [
                            DEF cylinder3 Shape {
                              appearance BrushedSteel {
                              }
                              geometry Cylinder {
                                height 0.06
                                radius 0.02
                              }
                            }
                            HingeJoint {
                              jointParameters HingeJointParameters {
                                position 426.5612570341007
                                axis 0 0 1
                                anchor 0.00237208 0.000614304 -0.0799754
                              }
                              device [
                                RotationalMotor {
                                  name "wheel1_right"
                                }
                              ]
                              endPoint Solid {
                                translation 0.0003702033289004099 -9.657315132261023e-05 -0.0800029613423352
                                rotation -0.40792150924338244 0.9130169999954589 -3.986657799665571e-06 3.1415920804837096
                                children [
                                  DEF wheel Shape {
                                    appearance ElectricConduit {
                                    }
                                    geometry Cylinder {
                                      height 0.09
                                      radius 0.15
                                    }
                                  }
                                ]
                                boundingObject USE wheel
                                physics Physics {
                                  mass 1
                                }
                                linearVelocity -0.0017182818331490035 0.0014396873316387276 -0.008505511527576174
                                angularVelocity 1.0889868812229113 3.822132462208912 0.4574017240753677
                              }
                            }
                          ]
                          boundingObject USE cylinder3
                          physics DEF phy1 Physics {
                            mass 1
                          }
                        }
                      ]
                      name "solid(1)"
                      boundingObject USE sphere1
                      physics USE phy1
                    }
                  ]
                  boundingObject USE cylinder2
                  physics USE phy1
                }
              ]
              boundingObject USE sphere1
              physics USE phy1
            }
          ]
          boundingObject USE cylinder1
          physics USE phy1
        }
      ]
      name "wheel1_right_system"
      physics DEF phy1 Physics {
        mass 1
      }
    }
    Solid {
      translation 0.18 0.24 0
      children [
        Solid {
          translation -0.000177663 0.0173403 0.0599364
          rotation -0.9999999929357695 8.124469320562993e-05 -8.676267159571073e-05 1.5708626067521982
          children [
            DEF cylinder1 Shape {
              appearance DamascusSteel {
              }
              geometry Cylinder {
                height 0.09
                radius 0.02
              }
            }
            Solid {
              translation 0 0 0.05
              children [
                DEF sphere1 Shape {
                  appearance BrushedSteel {
                  }
                  geometry Sphere {
                    radius 0.02
                  }
                }
                Solid {
                  translation 0 0.1 1.79608e-07
                  rotation -1 0 0 -1.5707953071795862
                  children [
                    DEF cylinder2 Shape {
                      appearance BrushedSteel {
                      }
                      geometry Cylinder {
                        height 0.2
                        radius 0.02
                      }
                    }
                    Solid {
                      translation 0 0 -0.11
                      children [
                        DEF sphere1 Shape {
                          appearance BrushedSteel {
                          }
                          geometry Sphere {
                            radius 0.02
                          }
                        }
                        Solid {
                          translation 0 0.03 -9.99999e-08
                          rotation 1 0 0 1.5708
                          children [
                            DEF cylinder3 Shape {
                              appearance BrushedSteel {
                              }
                              geometry Cylinder {
                                height 0.06
                                radius 0.02
                              }
                            }
                            HingeJoint {
                              jointParameters HingeJointParameters {
                                position 426.9614409310619
                                axis 0 0 1
                                anchor 0.00237208 0.000614304 -0.0799754
                              }
                              device [
                                RotationalMotor {
                                  name "wheel2_right"
                                }
                              ]
                              endPoint Solid {
                                translation 0.0004236181500823055 8.37118679285593e-05 -0.07999426430796319
                                rotation -0.5812537756184591 0.813722341053295 -1.7676561679109218e-07 3.1415862926383236
                                children [
                                  DEF wheel Shape {
                                    appearance ElectricConduit {
                                    }
                                    geometry Cylinder {
                                      height 0.09
                                      radius 0.15
                                    }
                                  }
                                ]
                                boundingObject USE wheel
                                physics Physics {
                                  mass 1
                                }
                                linearVelocity -0.0010412918916650193 0.0012103811426980196 -0.008043727344658858
                                angularVelocity 1.0889868788987735 3.822132454952725 0.4574017228114394
                              }
                            }
                          ]
                          boundingObject USE cylinder3
                          physics DEF phy1 Physics {
                            mass 1
                          }
                        }
                      ]
                      name "solid(1)"
                      boundingObject USE sphere1
                      physics USE phy1
                    }
                  ]
                  boundingObject USE cylinder2
                  physics USE phy1
                }
              ]
              boundingObject USE sphere1
              physics USE phy1
            }
          ]
          boundingObject USE cylinder1
          physics USE phy1
        }
      ]
      name "wheel2_right_system"
      physics DEF phy1 Physics {
        mass 1
      }
    }
  ]
  boundingObject DEF body Shape {
    appearance HammeredCopper {
    }
    geometry Cylinder {
      height 0.7
      radius 0.2
    }
  }
  physics DEF phy Physics {
    mass 1
  }
  controller "robo_controller"
  linearVelocity 0.00011426365282738032 -7.931921753886075e-05 -3.1092563274613116e-05
  angularVelocity 5.8557202602362826e-05 0.0004805293771653223 3.3893829392889426e-06
}
Solid {
  translation -9.53202391097532 -12.43130613800217 -2.0779145251752857
  rotation 0.028987052313973475 -0.03802872999028489 0.9988561290263342 2.2191357869215045
  children [
    DEF box Shape {
      appearance CorrugatedPvc {
        colorOverride 1 1 0
      }
      geometry Box {
        size 2.5 2 0.4
      }
    }
  ]
  boundingObject USE box
  physics USE phy1
  linearVelocity 3.286137157978415e-07 -4.035669095875877e-06 -3.429904918469161e-07
  angularVelocity -2.777658160281497e-08 -1.300385712806725e-08 -4.612588553790965e-08
}
Solid {
  translation -5.546097164584234 -0.0837626738611641 -0.49452388041234585
  rotation -0.042711971832229204 0.6876036235082458 0.7248289069846301 -3.0775884900940556
  children [
    DEF box Shape {
      appearance CorrugatedPvc {
        colorOverride 1 1 0
      }
      geometry Box {
        size 2.5 2 0.4
      }
    }
  ]
  name "solid(1)"
  boundingObject USE box
  physics USE phy1
  linearVelocity -6.077178080426672e-07 -1.5001066861086277e-06 -7.670442554561126e-08
  angularVelocity -3.818338638163728e-09 6.3265322937168345e-09 1.295042008667538e-07
}
